[2024-03-28T02:14:29.196+0000] {taskinstance.py:1979} INFO - Dependencies all met for dep_context=non-requeueable deps ti=<TaskInstance: dag_with_postgres_operator_v01.create_postgres_table scheduled__2024-03-25T00:00:00+00:00 [queued]>
[2024-03-28T02:14:29.201+0000] {taskinstance.py:1979} INFO - Dependencies all met for dep_context=requeueable deps ti=<TaskInstance: dag_with_postgres_operator_v01.create_postgres_table scheduled__2024-03-25T00:00:00+00:00 [queued]>
[2024-03-28T02:14:29.202+0000] {taskinstance.py:2193} INFO - Starting attempt 1 of 6
[2024-03-28T02:14:29.214+0000] {taskinstance.py:2217} INFO - Executing <Task(PostgresOperator): create_postgres_table> on 2024-03-25 00:00:00+00:00
[2024-03-28T02:14:29.217+0000] {standard_task_runner.py:60} INFO - Started process 839 to run task
[2024-03-28T02:14:29.221+0000] {standard_task_runner.py:87} INFO - Running: ['***', 'tasks', 'run', 'dag_with_postgres_operator_v01', 'create_postgres_table', 'scheduled__2024-03-25T00:00:00+00:00', '--job-id', '159', '--raw', '--subdir', 'DAGS_FOLDER/docker_with_postgres.py', '--cfg-path', '/tmp/tmpt8ea0b5n']
[2024-03-28T02:14:29.224+0000] {standard_task_runner.py:88} INFO - Job 159: Subtask create_postgres_table
[2024-03-28T02:14:29.261+0000] {task_command.py:423} INFO - Running <TaskInstance: dag_with_postgres_operator_v01.create_postgres_table scheduled__2024-03-25T00:00:00+00:00 [running]> on host 6ba63bfba168
[2024-03-28T02:14:29.308+0000] {taskinstance.py:2513} INFO - Exporting env vars: AIRFLOW_CTX_DAG_OWNER='ethan_wu' AIRFLOW_CTX_DAG_ID='dag_with_postgres_operator_v01' AIRFLOW_CTX_TASK_ID='create_postgres_table' AIRFLOW_CTX_EXECUTION_DATE='2024-03-25T00:00:00+00:00' AIRFLOW_CTX_TRY_NUMBER='1' AIRFLOW_CTX_DAG_RUN_ID='scheduled__2024-03-25T00:00:00+00:00'
[2024-03-28T02:14:29.309+0000] {sql.py:276} INFO - Executing: 
            create table if not exists dag_runs (
                dt date,
                dag_id character varying,
                primary key (dt, dag_id)
            )
            
[2024-03-28T02:14:29.314+0000] {base.py:83} INFO - Using connection ID 'postgres_localhost' for task execution.
[2024-03-28T02:14:29.320+0000] {base.py:83} INFO - Using connection ID 'postgres_localhost' for task execution.
[2024-03-28T02:14:37.325+0000] {taskinstance.py:2731} ERROR - Task failed with exception
Traceback (most recent call last):
  File "/home/airflow/.local/lib/python3.8/site-packages/airflow/models/taskinstance.py", line 444, in _execute_task
    result = _execute_callable(context=context, **execute_callable_kwargs)
  File "/home/airflow/.local/lib/python3.8/site-packages/airflow/models/taskinstance.py", line 414, in _execute_callable
    return execute_callable(context=context, **execute_callable_kwargs)
  File "/home/airflow/.local/lib/python3.8/site-packages/airflow/providers/common/sql/operators/sql.py", line 282, in execute
    output = hook.run(
  File "/home/airflow/.local/lib/python3.8/site-packages/airflow/providers/common/sql/hooks/sql.py", line 397, in run
    with closing(self.get_conn()) as conn:
  File "/home/airflow/.local/lib/python3.8/site-packages/airflow/providers/postgres/hooks/postgres.py", line 161, in get_conn
    self.conn = psycopg2.connect(**conn_args)
  File "/home/airflow/.local/lib/python3.8/site-packages/psycopg2/__init__.py", line 122, in connect
    conn = _connect(dsn, connection_factory=connection_factory, **kwasync)
psycopg2.OperationalError: could not translate host name "host.docker.local" to address: Temporary failure in name resolution

[2024-03-28T02:14:37.330+0000] {taskinstance.py:1149} INFO - Marking task as UP_FOR_RETRY. dag_id=dag_with_postgres_operator_v01, task_id=create_postgres_table, execution_date=20240325T000000, start_date=20240328T021429, end_date=20240328T021437
[2024-03-28T02:14:37.336+0000] {standard_task_runner.py:107} ERROR - Failed to execute job 159 for task create_postgres_table (could not translate host name "host.docker.local" to address: Temporary failure in name resolution
; 839)
[2024-03-28T02:14:37.369+0000] {local_task_job_runner.py:234} INFO - Task exited with return code 1
[2024-03-28T02:14:37.378+0000] {taskinstance.py:3312} INFO - 0 downstream tasks scheduled from follow-on schedule check
